<?xml version="1.0"?>
<robot name="body_link"
       xmlns:xi="http://www.w3.org/2001/XInclude">
  <link name="body_link">
    <visual>
      <origin xyz="0 0 0" rpy="0 -0 0"/>
      <geometry>
        <mesh filename="package://hrpsys_ros_bridge_robotis/models/OP3_meshes/body_link_mesh.dae" scale="1 1 1" />
      </geometry>
    </visual>
    <collision>
      <origin xyz="0 0 0" rpy="0 -0 0"/>
      <geometry>
        <mesh filename="package://hrpsys_ros_bridge_robotis/models/OP3_meshes/body_link_mesh.dae" scale="1 1 1" />
      </geometry>
    </collision>
    <inertial>
      <mass value="1.34928" />
      <origin xyz="-0.01501 0.00013 0.06582" rpy="0 -0 0"/>
      <inertia ixx="0.00340499" ixy="5.72e-06" ixz="-4.256e-05" iyy="0.00296939" iyz="-5.9e-07" izz="0.00317331"/>
    </inertial>
  </link>
  <gazebo reference="body_link">
    <mu1>0.9</mu1>
    <mu2>0.9</mu2>
  </gazebo>
  <link name="head_pan_link">
    <visual>
      <origin xyz="-0.001 0 0.1365" rpy="0 -0 0"/>
      <geometry>
        <mesh filename="package://hrpsys_ros_bridge_robotis/models/OP3_meshes/head_pan_link_mesh.dae" scale="1 1 1" />
      </geometry>
    </visual>
    <collision>
      <origin xyz="-0.001 0 0.1365" rpy="0 -0 0"/>
      <geometry>
        <mesh filename="package://hrpsys_ros_bridge_robotis/models/OP3_meshes/head_pan_link_mesh.dae" scale="1 1 1" />
      </geometry>
    </collision>
    <inertial>
      <mass value="0.01176" />
      <origin xyz="0.00233 0 0.00823" rpy="0 -0 0"/>
      <inertia ixx="3.97e-06" ixy="-2.48613e-22" ixz="-3.1e-07" iyy="1.65e-06" iyz="-3.95602e-22" izz="3.87e-06"/>
    </inertial>
  </link>
  <gazebo reference="head_pan_link">
    <mu1>0.9</mu1>
    <mu2>0.9</mu2>
  </gazebo>
  <link name="head_tilt_link">
    <visual>
      <origin xyz="0.01 0.019 0.0285" rpy="0 -0 0"/>
      <geometry>
        <mesh filename="package://hrpsys_ros_bridge_robotis/models/OP3_meshes/head_tilt_link_mesh.dae" scale="1 1 1" />
      </geometry>
    </visual>
    <collision>
      <origin xyz="0.01 0.019 0.0285" rpy="0 -0 0"/>
      <geometry>
        <mesh filename="package://hrpsys_ros_bridge_robotis/models/OP3_meshes/head_tilt_link_mesh.dae" scale="1 1 1" />
      </geometry>
    </collision>
    <inertial>
      <mass value="0.13631" />
      <origin xyz="0.0023 -0.01863 0.0277" rpy="0 -0 0"/>
      <inertia ixx="0.00010612" ixy="1.1e-07" ixz="-9.1e-06" iyy="8.721e-05" iyz="8.4e-07" izz="4.529e-05"/>
    </inertial>
  </link>
  <gazebo reference="head_tilt_link">
    <mu1>0.9</mu1>
    <mu2>0.9</mu2>
  </gazebo>
  <link name="l_hip_yaw_link">
    <visual>
      <origin xyz="0 0.035 0" rpy="0 -0 0"/>
      <geometry>
        <mesh filename="package://hrpsys_ros_bridge_robotis/models/OP3_meshes/l_hip_yaw_link_mesh.dae" scale="1 1 1" />
      </geometry>
    </visual>
    <collision>
      <origin xyz="0 0.035 0" rpy="0 -0 0"/>
      <geometry>
        <mesh filename="package://hrpsys_ros_bridge_robotis/models/OP3_meshes/l_hip_yaw_link_mesh.dae" scale="1 1 1" />
      </geometry>
    </collision>
    <inertial>
      <mass value="0.01181" />
      <origin xyz="-0.00157 0 -0.00774" rpy="0 -0 0"/>
      <inertia ixx="1.51e-06" ixy="1.83677e-21" ixz="1e-08" iyy="4.3e-06" iyz="3.80853e-24" izz="4.12e-06"/>
    </inertial>
  </link>
  <gazebo reference="l_hip_yaw_link">
    <mu1>0.9</mu1>
    <mu2>0.9</mu2>
  </gazebo>
  <link name="l_hip_roll_link">
    <visual>
      <origin xyz="-0.024 2.77556e-17 -0.0285" rpy="0 -0 0"/>
      <geometry>
        <mesh filename="package://hrpsys_ros_bridge_robotis/models/OP3_meshes/l_hip_roll_link_mesh.dae" scale="1 1 1" />
      </geometry>
    </visual>
    <collision>
      <origin xyz="-0.024 2.77556e-17 -0.0285" rpy="0 -0 0"/>
      <geometry>
        <mesh filename="package://hrpsys_ros_bridge_robotis/models/OP3_meshes/l_hip_roll_link_mesh.dae" scale="1 1 1" />
      </geometry>
    </collision>
    <inertial>
      <mass value="0.17886" />
      <origin xyz="0.00388 0.00028 -0.01214" rpy="0 -0 0"/>
      <inertia ixx="4.661e-05" ixy="-1.01e-06" ixz="-1.31e-06" iyy="0.00012523" iyz="-6e-08" izz="0.00010857"/>
    </inertial>
  </link>
  <gazebo reference="l_hip_roll_link">
    <mu1>0.9</mu1>
    <mu2>0.9</mu2>
  </gazebo>
  <link name="l_hip_pitch_link">
    <visual>
      <origin xyz="0.0241 0.019 8.32667e-17" rpy="0 -0 0"/>
      <geometry>
        <mesh filename="package://hrpsys_ros_bridge_robotis/models/OP3_meshes/l_hip_pitch_link_mesh.dae" scale="1 1 1" />
      </geometry>
    </visual>
    <collision>
      <origin xyz="0.0241 0.019 8.32667e-17" rpy="0 -0 0"/>
      <geometry>
        <mesh filename="package://hrpsys_ros_bridge_robotis/models/OP3_meshes/l_hip_pitch_link_mesh.dae" scale="1 1 1" />
      </geometry>
    </collision>
    <inertial>
      <mass value="0.11543" />
      <origin xyz="0.00059 -0.01901 -0.08408" rpy="0 -0 0"/>
      <inertia ixx="0.00010499" ixy="-1e-08" ixz="-7.1e-07" iyy="9.613e-05" iyz="3.53e-06" izz="2.493e-05"/>
    </inertial>
  </link>
  <gazebo reference="l_hip_pitch_link">
    <mu1>0.9</mu1>
    <mu2>0.9</mu2>
  </gazebo>
  <link name="l_knee_link">
    <visual>
      <origin xyz="-1.35525e-20 -6.93889e-16 -0.11015" rpy="0 -0 0"/>
      <geometry>
        <mesh filename="package://hrpsys_ros_bridge_robotis/models/OP3_meshes/l_knee_link_mesh.dae" scale="1 1 1" />
      </geometry>
    </visual>
    <collision>
      <origin xyz="-1.35525e-20 -6.93889e-16 -0.11015" rpy="0 -0 0"/>
      <geometry>
        <mesh filename="package://hrpsys_ros_bridge_robotis/models/OP3_meshes/l_knee_link_mesh.dae" scale="1 1 1" />
      </geometry>
    </collision>
    <inertial>
      <mass value="0.04015" />
      <origin xyz="0 -0.02151 -0.055" rpy="0 -0 0"/>
      <inertia ixx="3.715e-05" ixy="0" ixz="0" iyy="2.751e-05" iyz="0" izz="1.511e-05"/>
    </inertial>
  </link>
  <gazebo reference="l_knee_link">
    <mu1>0.9</mu1>
    <mu2>0.9</mu2>
  </gazebo>
  <link name="l_ank_pitch_link">
    <visual>
      <origin xyz="-7.72494e-19 -4.23273e-16 -0.11" rpy="0 -0 0"/>
      <geometry>
        <mesh filename="package://hrpsys_ros_bridge_robotis/models/OP3_meshes/l_ank_pitch_link_mesh.dae" scale="1 1 1" />
      </geometry>
    </visual>
    <collision>
      <origin xyz="-7.72494e-19 -4.23273e-16 -0.11" rpy="0 -0 0"/>
      <geometry>
        <mesh filename="package://hrpsys_ros_bridge_robotis/models/OP3_meshes/l_ank_pitch_link_mesh.dae" scale="1 1 1" />
      </geometry>
    </collision>
    <inertial>
      <mass value="0.17886" />
      <origin xyz="-0.02022 -0.01872 0.01214" rpy="0 -0 0"/>
      <inertia ixx="4.661e-05" ixy="-1.01e-06" ixz="1.31e-06" iyy="0.00012523" iyz="6e-08" izz="0.00010857"/>
    </inertial>
  </link>
  <gazebo reference="l_ank_pitch_link">
    <mu1>0.9</mu1>
    <mu2>0.9</mu2>
  </gazebo>
  <link name="l_ank_roll_link">
    <visual>
      <origin xyz="-0.0241 -0.019 -2.77556e-17" rpy="0 -0 0"/>
      <geometry>
        <mesh filename="package://hrpsys_ros_bridge_robotis/models/OP3_meshes/l_ank_roll_link_mesh.dae" scale="1 1 1" />
      </geometry>
    </visual>
    <collision>
      <origin xyz="-0.0241 -0.019 -2.77556e-17" rpy="0 -0 0"/>
      <geometry>
        <mesh filename="package://hrpsys_ros_bridge_robotis/models/OP3_meshes/l_ank_roll_link_mesh.dae" scale="1 1 1" />
      </geometry>
    </collision>
    <inertial>
      <mass value="0.06934" />
      <origin xyz="0.02373 0.01037 -0.0276" rpy="0 -0 0"/>
      <inertia ixx="4.034e-05" ixy="-1.9e-07" ixz="1.2e-07" iyy="7.874e-05" iyz="1.01e-06" izz="0.00011579"/>
    </inertial>
  </link>
  <gazebo reference="l_ank_roll_link">
    <mu1>0.9</mu1>
    <mu2>0.9</mu2>
  </gazebo>
  <link name="l_sho_pitch_link">
    <visual>
      <origin xyz="-0.001 0.06 0.111" rpy="0 -0 0"/>
      <geometry>
        <mesh filename="package://hrpsys_ros_bridge_robotis/models/OP3_meshes/l_sho_pitch_link_mesh.dae" scale="1 1 1" />
      </geometry>
    </visual>
    <collision>
      <origin xyz="-0.001 0.06 0.111" rpy="0 -0 0"/>
      <geometry>
        <mesh filename="package://hrpsys_ros_bridge_robotis/models/OP3_meshes/l_sho_pitch_link_mesh.dae" scale="1 1 1" />
      </geometry>
    </collision>
    <inertial>
      <mass value="0.01176" />
      <origin xyz="0 0.00823 -0.00233" rpy="0 -0 0"/>
      <inertia ixx="1.65e-06" ixy="-3.65567e-22" ixz="-4.79164e-22" iyy="3.87e-06" iyz="3.1e-07" izz="3.97e-06"/>
    </inertial>
  </link>
  <gazebo reference="l_sho_pitch_link">
    <mu1>0.9</mu1>
    <mu2>0.9</mu2>
  </gazebo>
  <link name="l_sho_roll_link">
    <visual>
      <origin xyz="0.019 0.0285 -0.01" rpy="0 -0 0"/>
      <geometry>
        <mesh filename="package://hrpsys_ros_bridge_robotis/models/OP3_meshes/l_sho_roll_link_mesh.dae" scale="1 1 1" />
      </geometry>
    </visual>
    <collision>
      <origin xyz="0.019 0.0285 -0.01" rpy="0 -0 0"/>
      <geometry>
        <mesh filename="package://hrpsys_ros_bridge_robotis/models/OP3_meshes/l_sho_roll_link_mesh.dae" scale="1 1 1" />
      </geometry>
    </collision>
    <inertial>
      <mass value="0.17758" />
      <origin xyz="-0.01844 0.04514 0.00028" rpy="0 -0 0"/>
      <inertia ixx="0.00022804" ixy="-1e-08" ixz="3e-08" iyy="3.042e-05" iyz="5.9e-07" izz="0.00023474"/>
    </inertial>
  </link>
  <gazebo reference="l_sho_roll_link">
    <mu1>0.9</mu1>
    <mu2>0.9</mu2>
  </gazebo>
  <link name="l_el_link">
    <visual>
      <origin xyz="-5.89806e-17 0.0904 -0.0001" rpy="0 -0 0"/>
      <geometry>
        <mesh filename="package://hrpsys_ros_bridge_robotis/models/OP3_meshes/l_el_link_mesh.dae" scale="1 1 1" />
      </geometry>
    </visual>
    <collision>
      <origin xyz="-5.89806e-17 0.0904 -0.0001" rpy="0 -0 0"/>
      <geometry>
        <mesh filename="package://hrpsys_ros_bridge_robotis/models/OP3_meshes/l_el_link_mesh.dae" scale="1 1 1" />
      </geometry>
    </collision>
    <inertial>
      <mass value="0.04127" />
      <origin xyz="-0.019 0.07033 0.0038" rpy="0 -0 0"/>
      <inertia ixx="6.196e-05" ixy="9.80813e-22" ixz="-2.97588e-21" iyy="1.231e-05" iyz="-3.72e-06" izz="6.854e-05"/>
    </inertial>
  </link>
  <gazebo reference="l_el_link">
    <mu1>0.9</mu1>
    <mu2>0.9</mu2>
  </gazebo>
  <link name="r_hip_yaw_link">
    <visual>
      <origin xyz="0 -0.035 0" rpy="0 -0 0"/>
      <geometry>
        <mesh filename="package://hrpsys_ros_bridge_robotis/models/OP3_meshes/r_hip_yaw_link_mesh.dae" scale="1 1 1" />
      </geometry>
    </visual>
    <collision>
      <origin xyz="0 -0.035 0" rpy="0 -0 0"/>
      <geometry>
        <mesh filename="package://hrpsys_ros_bridge_robotis/models/OP3_meshes/r_hip_yaw_link_mesh.dae" scale="1 1 1" />
      </geometry>
    </collision>
    <inertial>
      <mass value="0.01181" />
      <origin xyz="-0.00157 0 -0.00774" rpy="0 -0 0"/>
      <inertia ixx="1.51e-06" ixy="1.83677e-21" ixz="1e-08" iyy="4.3e-06" iyz="3.80853e-24" izz="4.12e-06"/>
    </inertial>
  </link>
  <gazebo reference="r_hip_yaw_link">
    <mu1>0.9</mu1>
    <mu2>0.9</mu2>
  </gazebo>
  <link name="r_hip_roll_link">
    <visual>
      <origin xyz="-0.024 -2.77556e-17 -0.0285" rpy="0 -0 0"/>
      <geometry>
        <mesh filename="package://hrpsys_ros_bridge_robotis/models/OP3_meshes/r_hip_roll_link_mesh.dae" scale="1 1 1" />
      </geometry>
    </visual>
    <collision>
      <origin xyz="-0.024 -2.77556e-17 -0.0285" rpy="0 -0 0"/>
      <geometry>
        <mesh filename="package://hrpsys_ros_bridge_robotis/models/OP3_meshes/r_hip_roll_link_mesh.dae" scale="1 1 1" />
      </geometry>
    </collision>
    <inertial>
      <mass value="0.17886" />
      <origin xyz="0.00388 -0.00028 -0.01214" rpy="0 -0 0"/>
      <inertia ixx="4.661e-05" ixy="1.01e-06" ixz="-1.31e-06" iyy="0.00012523" iyz="6e-08" izz="0.00010857"/>
    </inertial>
  </link>
  <gazebo reference="r_hip_roll_link">
    <mu1>0.9</mu1>
    <mu2>0.9</mu2>
  </gazebo>
  <link name="r_hip_pitch_link">
    <visual>
      <origin xyz="0.0241 -0.019 -2.77556e-17" rpy="0 -0 0"/>
      <geometry>
        <mesh filename="package://hrpsys_ros_bridge_robotis/models/OP3_meshes/r_hip_pitch_link_mesh.dae" scale="1 1 1" />
      </geometry>
    </visual>
    <collision>
      <origin xyz="0.0241 -0.019 -2.77556e-17" rpy="0 -0 0"/>
      <geometry>
        <mesh filename="package://hrpsys_ros_bridge_robotis/models/OP3_meshes/r_hip_pitch_link_mesh.dae" scale="1 1 1" />
      </geometry>
    </collision>
    <inertial>
      <mass value="0.11543" />
      <origin xyz="0.00059 0.01901 -0.08408" rpy="0 -0 0"/>
      <inertia ixx="0.00010499" ixy="1e-08" ixz="-7.1e-07" iyy="9.613e-05" iyz="-3.53e-06" izz="2.493e-05"/>
    </inertial>
  </link>
  <gazebo reference="r_hip_pitch_link">
    <mu1>0.9</mu1>
    <mu2>0.9</mu2>
  </gazebo>
  <link name="r_knee_link">
    <visual>
      <origin xyz="-1.35525e-20 7.42462e-16 -0.11015" rpy="0 -0 0"/>
      <geometry>
        <mesh filename="package://hrpsys_ros_bridge_robotis/models/OP3_meshes/r_knee_link_mesh.dae" scale="1 1 1" />
      </geometry>
    </visual>
    <collision>
      <origin xyz="-1.35525e-20 7.42462e-16 -0.11015" rpy="0 -0 0"/>
      <geometry>
        <mesh filename="package://hrpsys_ros_bridge_robotis/models/OP3_meshes/r_knee_link_mesh.dae" scale="1 1 1" />
      </geometry>
    </collision>
    <inertial>
      <mass value="0.04015" />
      <origin xyz="0 0.02151 -0.055" rpy="0 -0 0"/>
      <inertia ixx="3.715e-05" ixy="0" ixz="0" iyy="2.751e-05" iyz="0" izz="1.511e-05"/>
    </inertial>
  </link>
  <gazebo reference="r_knee_link">
    <mu1>0.9</mu1>
    <mu2>0.9</mu2>
  </gazebo>
  <link name="r_ank_pitch_link">
    <visual>
      <origin xyz="-7.72494e-19 4.23273e-16 -0.11" rpy="0 -0 0"/>
      <geometry>
        <mesh filename="package://hrpsys_ros_bridge_robotis/models/OP3_meshes/r_ank_pitch_link_mesh.dae" scale="1 1 1" />
      </geometry>
    </visual>
    <collision>
      <origin xyz="-7.72494e-19 4.23273e-16 -0.11" rpy="0 -0 0"/>
      <geometry>
        <mesh filename="package://hrpsys_ros_bridge_robotis/models/OP3_meshes/r_ank_pitch_link_mesh.dae" scale="1 1 1" />
      </geometry>
    </collision>
    <inertial>
      <mass value="0.17886" />
      <origin xyz="-0.02022 0.01872 0.01214" rpy="0 -0 0"/>
      <inertia ixx="4.661e-05" ixy="1.01e-06" ixz="1.31e-06" iyy="0.00012523" iyz="-6e-08" izz="0.00010857"/>
    </inertial>
  </link>
  <gazebo reference="r_ank_pitch_link">
    <mu1>0.9</mu1>
    <mu2>0.9</mu2>
  </gazebo>
  <link name="r_ank_roll_link">
    <visual>
      <origin xyz="-0.0241 0.019 -2.77556e-17" rpy="0 -0 0"/>
      <geometry>
        <mesh filename="package://hrpsys_ros_bridge_robotis/models/OP3_meshes/r_ank_roll_link_mesh.dae" scale="1 1 1" />
      </geometry>
    </visual>
    <collision>
      <origin xyz="-0.0241 0.019 -2.77556e-17" rpy="0 -0 0"/>
      <geometry>
        <mesh filename="package://hrpsys_ros_bridge_robotis/models/OP3_meshes/r_ank_roll_link_mesh.dae" scale="1 1 1" />
      </geometry>
    </collision>
    <inertial>
      <mass value="0.06934" />
      <origin xyz="0.02373 -0.01037 -0.0276" rpy="0 -0 0"/>
      <inertia ixx="4.034e-05" ixy="1.9e-07" ixz="1.2e-07" iyy="7.874e-05" iyz="-1.01e-06" izz="0.00011579"/>
    </inertial>
  </link>
  <gazebo reference="r_ank_roll_link">
    <mu1>0.9</mu1>
    <mu2>0.9</mu2>
  </gazebo>
  <link name="r_sho_pitch_link">
    <visual>
      <origin xyz="-0.001 -0.06 0.111" rpy="0 -0 0"/>
      <geometry>
        <mesh filename="package://hrpsys_ros_bridge_robotis/models/OP3_meshes/r_sho_pitch_link_mesh.dae" scale="1 1 1" />
      </geometry>
    </visual>
    <collision>
      <origin xyz="-0.001 -0.06 0.111" rpy="0 -0 0"/>
      <geometry>
        <mesh filename="package://hrpsys_ros_bridge_robotis/models/OP3_meshes/r_sho_pitch_link_mesh.dae" scale="1 1 1" />
      </geometry>
    </collision>
    <inertial>
      <mass value="0.01176" />
      <origin xyz="0 -0.00823 -0.00233" rpy="0 -0 0"/>
      <inertia ixx="1.65e-06" ixy="3.65567e-22" ixz="-4.79164e-22" iyy="3.87e-06" iyz="-3.1e-07" izz="3.97e-06"/>
    </inertial>
  </link>
  <gazebo reference="r_sho_pitch_link">
    <mu1>0.9</mu1>
    <mu2>0.9</mu2>
  </gazebo>
  <link name="r_sho_roll_link">
    <visual>
      <origin xyz="0.019 -0.0285 -0.01" rpy="0 -0 0"/>
      <geometry>
        <mesh filename="package://hrpsys_ros_bridge_robotis/models/OP3_meshes/r_sho_roll_link_mesh.dae" scale="1 1 1" />
      </geometry>
    </visual>
    <collision>
      <origin xyz="0.019 -0.0285 -0.01" rpy="0 -0 0"/>
      <geometry>
        <mesh filename="package://hrpsys_ros_bridge_robotis/models/OP3_meshes/r_sho_roll_link_mesh.dae" scale="1 1 1" />
      </geometry>
    </collision>
    <inertial>
      <mass value="0.17758" />
      <origin xyz="-0.01844 -0.04514 0.00028" rpy="0 -0 0"/>
      <inertia ixx="0.00022804" ixy="1e-08" ixz="3e-08" iyy="3.042e-05" iyz="-5.9e-07" izz="0.00023474"/>
    </inertial>
  </link>
  <gazebo reference="r_sho_roll_link">
    <mu1>0.9</mu1>
    <mu2>0.9</mu2>
  </gazebo>
  <link name="r_el_link">
    <visual>
      <origin xyz="-5.89806e-17 -0.0904 -0.0001" rpy="0 -0 0"/>
      <geometry>
        <mesh filename="package://hrpsys_ros_bridge_robotis/models/OP3_meshes/r_el_link_mesh.dae" scale="1 1 1" />
      </geometry>
    </visual>
    <collision>
      <origin xyz="-5.89806e-17 -0.0904 -0.0001" rpy="0 -0 0"/>
      <geometry>
        <mesh filename="package://hrpsys_ros_bridge_robotis/models/OP3_meshes/r_el_link_mesh.dae" scale="1 1 1" />
      </geometry>
    </collision>
    <inertial>
      <mass value="0.04127" />
      <origin xyz="-0.019 -0.07033 0.0038" rpy="0 -0 0"/>
      <inertia ixx="6.196e-05" ixy="-9.80813e-22" ixz="-2.97588e-21" iyy="1.231e-05" iyz="3.72e-06" izz="6.854e-05"/>
    </inertial>
  </link>
  <gazebo reference="r_el_link">
    <mu1>0.9</mu1>
    <mu2>0.9</mu2>
  </gazebo>
  <joint name="head_pan" type="revolute">
    <parent link="body_link"/>
    <child  link="head_pan_link"/>
    <origin xyz="-0.001 0 0.1365" rpy="0 -0 0 "/>
    <axis   xyz="0 0 1"/>
    <limit lower="-2.82743" upper="2.82743" effort="1000" velocity="100" />
    <dynamics damping="0.2" friction="0" />
  </joint>
  <transmission type="pr2_mechanism_model/SimpleTransmission" name="head_pan_trans" >
    <actuator name="head_pan_motor" />
    <joint name="head_pan" />
    <mechanicalReduction>1</mechanicalReduction>
  </transmission>
  <gazebo reference="head_pan">
    <cfmDamping>0.4</cfmDamping>
  </gazebo>
  <joint name="head_tilt" type="revolute">
    <parent link="head_pan_link"/>
    <child  link="head_tilt_link"/>
    <origin xyz="0.01 0.019 0.0285" rpy="0 -0 0 "/>
    <axis   xyz="0 -1 0"/>
    <limit lower="-2.82743" upper="2.82743" effort="1000" velocity="100" />
    <dynamics damping="0.2" friction="0" />
  </joint>
  <transmission type="pr2_mechanism_model/SimpleTransmission" name="head_tilt_trans" >
    <actuator name="head_tilt_motor" />
    <joint name="head_tilt" />
    <mechanicalReduction>1</mechanicalReduction>
  </transmission>
  <gazebo reference="head_tilt">
    <cfmDamping>0.4</cfmDamping>
  </gazebo>
  <joint name="l_hip_yaw" type="revolute">
    <parent link="body_link"/>
    <child  link="l_hip_yaw_link"/>
    <origin xyz="0 0.035 0" rpy="0 -0 0 "/>
    <axis   xyz="0 0 -1"/>
    <limit lower="-2.82743" upper="2.82743" effort="1000" velocity="100" />
    <dynamics damping="0.2" friction="0" />
  </joint>
  <transmission type="pr2_mechanism_model/SimpleTransmission" name="l_hip_yaw_trans" >
    <actuator name="l_hip_yaw_motor" />
    <joint name="l_hip_yaw" />
    <mechanicalReduction>1</mechanicalReduction>
  </transmission>
  <gazebo reference="l_hip_yaw">
    <cfmDamping>0.4</cfmDamping>
  </gazebo>
  <joint name="l_hip_roll" type="revolute">
    <parent link="l_hip_yaw_link"/>
    <child  link="l_hip_roll_link"/>
    <origin xyz="-0.024 2.77556e-17 -0.0285" rpy="0 -0 0 "/>
    <axis   xyz="-1 0 0"/>
    <limit lower="-2.82743" upper="2.82743" effort="1000" velocity="100" />
    <dynamics damping="0.2" friction="0" />
  </joint>
  <transmission type="pr2_mechanism_model/SimpleTransmission" name="l_hip_roll_trans" >
    <actuator name="l_hip_roll_motor" />
    <joint name="l_hip_roll" />
    <mechanicalReduction>1</mechanicalReduction>
  </transmission>
  <gazebo reference="l_hip_roll">
    <cfmDamping>0.4</cfmDamping>
  </gazebo>
  <joint name="l_hip_pitch" type="revolute">
    <parent link="l_hip_roll_link"/>
    <child  link="l_hip_pitch_link"/>
    <origin xyz="0.0241 0.019 8.32667e-17" rpy="0 -0 0 "/>
    <axis   xyz="0 1 0"/>
    <limit lower="-2.82743" upper="2.82743" effort="1000" velocity="100" />
    <dynamics damping="0.2" friction="0" />
  </joint>
  <transmission type="pr2_mechanism_model/SimpleTransmission" name="l_hip_pitch_trans" >
    <actuator name="l_hip_pitch_motor" />
    <joint name="l_hip_pitch" />
    <mechanicalReduction>1</mechanicalReduction>
  </transmission>
  <gazebo reference="l_hip_pitch">
    <cfmDamping>0.4</cfmDamping>
  </gazebo>
  <joint name="l_knee" type="revolute">
    <parent link="l_hip_pitch_link"/>
    <child  link="l_knee_link"/>
    <origin xyz="-1.35525e-20 -6.93889e-16 -0.11015" rpy="0 -0 0 "/>
    <axis   xyz="0 1 0"/>
    <limit lower="-2.82743" upper="2.82743" effort="1000" velocity="100" />
    <dynamics damping="0.2" friction="0" />
  </joint>
  <transmission type="pr2_mechanism_model/SimpleTransmission" name="l_knee_trans" >
    <actuator name="l_knee_motor" />
    <joint name="l_knee" />
    <mechanicalReduction>1</mechanicalReduction>
  </transmission>
  <gazebo reference="l_knee">
    <cfmDamping>0.4</cfmDamping>
  </gazebo>
  <joint name="l_ank_pitch" type="revolute">
    <parent link="l_knee_link"/>
    <child  link="l_ank_pitch_link"/>
    <origin xyz="-7.72494e-19 -4.23273e-16 -0.11" rpy="0 -0 0 "/>
    <axis   xyz="0 -1 0"/>
    <limit lower="-2.82743" upper="2.82743" effort="1000" velocity="100" />
    <dynamics damping="0.2" friction="0" />
  </joint>
  <transmission type="pr2_mechanism_model/SimpleTransmission" name="l_ank_pitch_trans" >
    <actuator name="l_ank_pitch_motor" />
    <joint name="l_ank_pitch" />
    <mechanicalReduction>1</mechanicalReduction>
  </transmission>
  <gazebo reference="l_ank_pitch">
    <cfmDamping>0.4</cfmDamping>
  </gazebo>
  <joint name="l_ank_roll" type="revolute">
    <parent link="l_ank_pitch_link"/>
    <child  link="l_ank_roll_link"/>
    <origin xyz="-0.0241 -0.019 -2.77556e-17" rpy="0 -0 0 "/>
    <axis   xyz="1 0 0"/>
    <limit lower="-2.82743" upper="2.82743" effort="1000" velocity="100" />
    <dynamics damping="0.2" friction="0" />
  </joint>
  <transmission type="pr2_mechanism_model/SimpleTransmission" name="l_ank_roll_trans" >
    <actuator name="l_ank_roll_motor" />
    <joint name="l_ank_roll" />
    <mechanicalReduction>1</mechanicalReduction>
  </transmission>
  <gazebo reference="l_ank_roll">
    <cfmDamping>0.4</cfmDamping>
  </gazebo>
  <joint name="l_sho_pitch" type="revolute">
    <parent link="body_link"/>
    <child  link="l_sho_pitch_link"/>
    <origin xyz="-0.001 0.06 0.111" rpy="0 -0 0 "/>
    <axis   xyz="0 1 0"/>
    <limit lower="-2.82743" upper="2.82743" effort="1000" velocity="100" />
    <dynamics damping="0.2" friction="0" />
  </joint>
  <transmission type="pr2_mechanism_model/SimpleTransmission" name="l_sho_pitch_trans" >
    <actuator name="l_sho_pitch_motor" />
    <joint name="l_sho_pitch" />
    <mechanicalReduction>1</mechanicalReduction>
  </transmission>
  <gazebo reference="l_sho_pitch">
    <cfmDamping>0.4</cfmDamping>
  </gazebo>
  <joint name="l_sho_roll" type="revolute">
    <parent link="l_sho_pitch_link"/>
    <child  link="l_sho_roll_link"/>
    <origin xyz="0.019 0.0285 -0.01" rpy="0 -0 0 "/>
    <axis   xyz="-1 0 0"/>
    <limit lower="-2.82743" upper="2.82743" effort="1000" velocity="100" />
    <dynamics damping="0.2" friction="0" />
  </joint>
  <transmission type="pr2_mechanism_model/SimpleTransmission" name="l_sho_roll_trans" >
    <actuator name="l_sho_roll_motor" />
    <joint name="l_sho_roll" />
    <mechanicalReduction>1</mechanicalReduction>
  </transmission>
  <gazebo reference="l_sho_roll">
    <cfmDamping>0.4</cfmDamping>
  </gazebo>
  <joint name="l_el" type="revolute">
    <parent link="l_sho_roll_link"/>
    <child  link="l_el_link"/>
    <origin xyz="-5.89806e-17 0.0904 -0.0001" rpy="0 -0 0 "/>
    <axis   xyz="1 0 0"/>
    <limit lower="-2.82743" upper="2.82743" effort="1000" velocity="100" />
    <dynamics damping="0.2" friction="0" />
  </joint>
  <transmission type="pr2_mechanism_model/SimpleTransmission" name="l_el_trans" >
    <actuator name="l_el_motor" />
    <joint name="l_el" />
    <mechanicalReduction>1</mechanicalReduction>
  </transmission>
  <gazebo reference="l_el">
    <cfmDamping>0.4</cfmDamping>
  </gazebo>
  <joint name="r_hip_yaw" type="revolute">
    <parent link="body_link"/>
    <child  link="r_hip_yaw_link"/>
    <origin xyz="0 -0.035 0" rpy="0 -0 0 "/>
    <axis   xyz="0 0 -1"/>
    <limit lower="-2.82743" upper="2.82743" effort="1000" velocity="100" />
    <dynamics damping="0.2" friction="0" />
  </joint>
  <transmission type="pr2_mechanism_model/SimpleTransmission" name="r_hip_yaw_trans" >
    <actuator name="r_hip_yaw_motor" />
    <joint name="r_hip_yaw" />
    <mechanicalReduction>1</mechanicalReduction>
  </transmission>
  <gazebo reference="r_hip_yaw">
    <cfmDamping>0.4</cfmDamping>
  </gazebo>
  <joint name="r_hip_roll" type="revolute">
    <parent link="r_hip_yaw_link"/>
    <child  link="r_hip_roll_link"/>
    <origin xyz="-0.024 -2.77556e-17 -0.0285" rpy="0 -0 0 "/>
    <axis   xyz="-1 0 0"/>
    <limit lower="-2.82743" upper="2.82743" effort="1000" velocity="100" />
    <dynamics damping="0.2" friction="0" />
  </joint>
  <transmission type="pr2_mechanism_model/SimpleTransmission" name="r_hip_roll_trans" >
    <actuator name="r_hip_roll_motor" />
    <joint name="r_hip_roll" />
    <mechanicalReduction>1</mechanicalReduction>
  </transmission>
  <gazebo reference="r_hip_roll">
    <cfmDamping>0.4</cfmDamping>
  </gazebo>
  <joint name="r_hip_pitch" type="revolute">
    <parent link="r_hip_roll_link"/>
    <child  link="r_hip_pitch_link"/>
    <origin xyz="0.0241 -0.019 -2.77556e-17" rpy="0 -0 0 "/>
    <axis   xyz="0 -1 0"/>
    <limit lower="-2.82743" upper="2.82743" effort="1000" velocity="100" />
    <dynamics damping="0.2" friction="0" />
  </joint>
  <transmission type="pr2_mechanism_model/SimpleTransmission" name="r_hip_pitch_trans" >
    <actuator name="r_hip_pitch_motor" />
    <joint name="r_hip_pitch" />
    <mechanicalReduction>1</mechanicalReduction>
  </transmission>
  <gazebo reference="r_hip_pitch">
    <cfmDamping>0.4</cfmDamping>
  </gazebo>
  <joint name="r_knee" type="revolute">
    <parent link="r_hip_pitch_link"/>
    <child  link="r_knee_link"/>
    <origin xyz="-1.35525e-20 7.42462e-16 -0.11015" rpy="0 -0 0 "/>
    <axis   xyz="0 -1 0"/>
    <limit lower="-2.82743" upper="2.82743" effort="1000" velocity="100" />
    <dynamics damping="0.2" friction="0" />
  </joint>
  <transmission type="pr2_mechanism_model/SimpleTransmission" name="r_knee_trans" >
    <actuator name="r_knee_motor" />
    <joint name="r_knee" />
    <mechanicalReduction>1</mechanicalReduction>
  </transmission>
  <gazebo reference="r_knee">
    <cfmDamping>0.4</cfmDamping>
  </gazebo>
  <joint name="r_ank_pitch" type="revolute">
    <parent link="r_knee_link"/>
    <child  link="r_ank_pitch_link"/>
    <origin xyz="-7.72494e-19 4.23273e-16 -0.11" rpy="0 -0 0 "/>
    <axis   xyz="0 1 0"/>
    <limit lower="-2.82743" upper="2.82743" effort="1000" velocity="100" />
    <dynamics damping="0.2" friction="0" />
  </joint>
  <transmission type="pr2_mechanism_model/SimpleTransmission" name="r_ank_pitch_trans" >
    <actuator name="r_ank_pitch_motor" />
    <joint name="r_ank_pitch" />
    <mechanicalReduction>1</mechanicalReduction>
  </transmission>
  <gazebo reference="r_ank_pitch">
    <cfmDamping>0.4</cfmDamping>
  </gazebo>
  <joint name="r_ank_roll" type="revolute">
    <parent link="r_ank_pitch_link"/>
    <child  link="r_ank_roll_link"/>
    <origin xyz="-0.0241 0.019 -2.77556e-17" rpy="0 -0 0 "/>
    <axis   xyz="1 0 0"/>
    <limit lower="-2.82743" upper="2.82743" effort="1000" velocity="100" />
    <dynamics damping="0.2" friction="0" />
  </joint>
  <transmission type="pr2_mechanism_model/SimpleTransmission" name="r_ank_roll_trans" >
    <actuator name="r_ank_roll_motor" />
    <joint name="r_ank_roll" />
    <mechanicalReduction>1</mechanicalReduction>
  </transmission>
  <gazebo reference="r_ank_roll">
    <cfmDamping>0.4</cfmDamping>
  </gazebo>
  <joint name="r_sho_pitch" type="revolute">
    <parent link="body_link"/>
    <child  link="r_sho_pitch_link"/>
    <origin xyz="-0.001 -0.06 0.111" rpy="0 -0 0 "/>
    <axis   xyz="0 -1 0"/>
    <limit lower="-2.82743" upper="2.82743" effort="1000" velocity="100" />
    <dynamics damping="0.2" friction="0" />
  </joint>
  <transmission type="pr2_mechanism_model/SimpleTransmission" name="r_sho_pitch_trans" >
    <actuator name="r_sho_pitch_motor" />
    <joint name="r_sho_pitch" />
    <mechanicalReduction>1</mechanicalReduction>
  </transmission>
  <gazebo reference="r_sho_pitch">
    <cfmDamping>0.4</cfmDamping>
  </gazebo>
  <joint name="r_sho_roll" type="revolute">
    <parent link="r_sho_pitch_link"/>
    <child  link="r_sho_roll_link"/>
    <origin xyz="0.019 -0.0285 -0.01" rpy="0 -0 0 "/>
    <axis   xyz="-1 0 0"/>
    <limit lower="-2.82743" upper="2.82743" effort="1000" velocity="100" />
    <dynamics damping="0.2" friction="0" />
  </joint>
  <transmission type="pr2_mechanism_model/SimpleTransmission" name="r_sho_roll_trans" >
    <actuator name="r_sho_roll_motor" />
    <joint name="r_sho_roll" />
    <mechanicalReduction>1</mechanicalReduction>
  </transmission>
  <gazebo reference="r_sho_roll">
    <cfmDamping>0.4</cfmDamping>
  </gazebo>
  <joint name="r_el" type="revolute">
    <parent link="r_sho_roll_link"/>
    <child  link="r_el_link"/>
    <origin xyz="-5.89806e-17 -0.0904 -0.0001" rpy="0 -0 0 "/>
    <axis   xyz="1 0 0"/>
    <limit lower="-2.82743" upper="2.82743" effort="1000" velocity="100" />
    <dynamics damping="0.2" friction="0" />
  </joint>
  <transmission type="pr2_mechanism_model/SimpleTransmission" name="r_el_trans" >
    <actuator name="r_el_motor" />
    <joint name="r_el" />
    <mechanicalReduction>1</mechanicalReduction>
  </transmission>
  <gazebo reference="r_el">
    <cfmDamping>0.4</cfmDamping>
  </gazebo>
</robot>
